<?xml version="1.0" encoding="utf-8"?>
<!-- This URDF was automatically created by SolidWorks to URDF Exporter! Originally created by Stephen Brawner (brawner@gmail.com) 
     Commit Version: 1.5.1-0-g916b5db  Build Version: 1.5.7152.31018
     For more information, please see http://wiki.ros.org/sw_urdf_exporter -->
<robot
  name="ExoMy_Model_Full">
  <link
    name="base_link">
    <inertial>
      <origin
        xyz="0.0034422 -0.00059358 0.080023"
        rpy="0 0 0" />
      <mass
        value="0.46179" />
      <inertia
        ixx="0.0010394"
        ixy="5.8492E-06"
        ixz="-4.2179E-06"
        iyy="0.0014555"
        iyz="5.857E-06"
        izz="0.0018135" />
    </inertial>
    <visual>
      <origin
        xyz="0 0 0"
        rpy="0 0 0" />
      <geometry>
        <mesh
          filename="package://ExoMy_Model_Full/meshes/base_link.STL" />
      </geometry>
      <material
        name="">
        <color
          rgba="0.29804 0.29804 0.29804 1" />
      </material>
    </visual>
    <collision>
      <origin
        xyz="0 0 0"
        rpy="0 0 0" />
      <geometry>
        <mesh
          filename="package://ExoMy_Model_Full/meshes/base_link.STL" />
      </geometry>
    </collision>
  </link>
  <link
    name="MRB_link">
    <inertial>
      <origin
        xyz="-4.7549E-06 0.0051724 -0.053204"
        rpy="0 0 0" />
      <mass
        value="0.10838" />
      <inertia
        ixx="4.8736E-05"
        ixy="1.487E-09"
        ixz="1.5114E-08"
        iyy="0.00029223"
        iyz="-2.6526E-07"
        izz="0.0002574" />
    </inertial>
    <visual>
      <origin
        xyz="0 0 0"
        rpy="0 0 0" />
      <geometry>
        <mesh
          filename="package://ExoMy_Model_Full/meshes/MRB_link.STL" />
      </geometry>
      <material
        name="">
        <color
          rgba="0.29804 0.29804 0.29804 1" />
      </material>
    </visual>
    <collision>
      <origin
        xyz="0 0 0"
        rpy="0 0 0" />
      <geometry>
        <mesh
          filename="package://ExoMy_Model_Full/meshes/MRB_link.STL" />
      </geometry>
    </collision>
  </link>
  <joint
    name="MRB_joint"
    type="revolute">
    <origin
      xyz="-0.082 0 0.017"
      rpy="1.5708 0 1.5708" />
    <parent
      link="base_link" />
    <child
      link="MRB_link" />
    <axis
      xyz="0 0 -1" />
    <limit
      lower="1"
      upper="1"
      effort="0"
      velocity="0" />
  </joint>
  <link
    name="STR_LR_link">
    <inertial>
      <origin
        xyz="-0.012457 0.00022549 -0.033761"
        rpy="0 0 0" />
      <mass
        value="0.071174" />
      <inertia
        ixx="3.3688E-05"
        ixy="-8.9803E-09"
        ixz="-4.7385E-06"
        iyy="4.106E-05"
        iyz="-1.4036E-07"
        izz="1.5915E-05" />
    </inertial>
    <visual>
      <origin
        xyz="0 0 0"
        rpy="0 0 0" />
      <geometry>
        <mesh
          filename="package://ExoMy_Model_Full/meshes/STR_LR_link.STL" />
      </geometry>
      <material
        name="">
        <color
          rgba="0.69804 0.69804 0.69804 1" />
      </material>
    </visual>
    <collision>
      <origin
        xyz="0 0 0"
        rpy="0 0 0" />
      <geometry>
        <mesh
          filename="package://ExoMy_Model_Full/meshes/STR_LR_link.STL" />
      </geometry>
    </collision>
  </link>
  <joint
    name="STR_LR_joint"
    type="revolute">
    <origin
      xyz="0.10378 -0.015418 -0.080775"
      rpy="1.5708 -1.5708 0" />
    <parent
      link="MRB_link" />
    <child
      link="STR_LR_link" />
    <axis
      xyz="0 0 -1" />
    <limit
      lower="-1.57"
      upper="1.57"
      effort="0"
      velocity="0" />
  </joint>
  <link
    name="DRV_LR_link">
    <inertial>
      <origin
        xyz="0.031467 0.072872 0.10378"
        rpy="0 0 0" />
      <mass
        value="0.056973" />
      <inertia
        ixx="8.0499E-05"
        ixy="-6.3012E-08"
        ixz="1.2131E-11"
        iyy="5.2111E-05"
        iyz="1.4281E-11"
        izz="5.2306E-05" />
    </inertial>
    <visual>
      <origin
        xyz="0 0 0"
        rpy="0 0 0" />
      <geometry>
        <mesh
          filename="package://ExoMy_Model_Full/meshes/DRV_LR_link.STL" />
      </geometry>
      <material
        name="">
        <color
          rgba="0.96863 0.87843 0.6 1" />
      </material>
    </visual>
    <collision>
      <origin
        xyz="0 0 0"
        rpy="0 0 0" />
      <geometry>
        <mesh
          filename="package://ExoMy_Model_Full/meshes/DRV_LR_link.STL" />
      </geometry>
    </collision>
  </link>
  <joint
    name="DRV_LR_joint"
    type="continuous">
    <origin
      xyz="-0.021614 -0.10378 0.015418"
      rpy="-1.5708 0 0" />
    <parent
      link="STR_LR_link" />
    <child
      link="DRV_LR_link" />
    <axis
      xyz="0 0 1" />
  </joint>
  <link
    name="STR_RR_link">
    <inertial>
      <origin
        xyz="-0.0124555119207004 -0.000225533347028822 -0.0337608863888986"
        rpy="0 0 0" />
      <mass
        value="0.071173105016733" />
      <inertia
        ixx="3.36872651590183E-05"
        ixy="8.07921081357608E-09"
        ixz="-4.74135535852484E-06"
        iyy="4.10633342810781E-05"
        iyz="1.40511475060575E-07"
        izz="1.59192004795905E-05" />
    </inertial>
    <visual>
      <origin
        xyz="0 0 0"
        rpy="0 0 0" />
      <geometry>
        <mesh
          filename="package://ExoMy_Model_Full/meshes/STR_RR_link.STL" />
      </geometry>
      <material
        name="">
        <color
          rgba="0.698039215686274 0.698039215686274 0.698039215686274 1" />
      </material>
    </visual>
    <collision>
      <origin
        xyz="0 0 0"
        rpy="0 0 0" />
      <geometry>
        <mesh
          filename="package://ExoMy_Model_Full/meshes/STR_RR_link.STL" />
      </geometry>
    </collision>
  </link>
  <joint
    name="STR_RR_joint"
    type="revolute">
    <origin
      xyz="-0.10378 -0.015418 -0.080775"
      rpy="1.5708 -1.5708 0" />
    <parent
      link="MRB_link" />
    <child
      link="STR_RR_link" />
    <axis
      xyz="0 0 -1" />
    <limit
      lower="0"
      upper="0"
      effort="0"
      velocity="0" />
  </joint>
  <link
    name="DRV_RR_link">
    <inertial>
      <origin
        xyz="0.0314671815371365 0.0728723179165185 -0.103780043928043"
        rpy="0 0 0" />
      <mass
        value="0.0569725827075564" />
      <inertia
        ixx="8.04986816304343E-05"
        ixy="-6.3011767107178E-08"
        ixz="1.21312261112933E-11"
        iyy="5.21106389985384E-05"
        iyz="1.42808035674551E-11"
        izz="5.23057476713962E-05" />
    </inertial>
    <visual>
      <origin
        xyz="0 0 0"
        rpy="0 0 0" />
      <geometry>
        <mesh
          filename="package://ExoMy_Model_Full/meshes/DRV_RR_link.STL" />
      </geometry>
      <material
        name="">
        <color
          rgba="0.968627450980392 0.87843137254902 0.6 1" />
      </material>
    </visual>
    <collision>
      <origin
        xyz="0 0 0"
        rpy="0 0 0" />
      <geometry>
        <mesh
          filename="package://ExoMy_Model_Full/meshes/DRV_RR_link.STL" />
      </geometry>
    </collision>
  </link>
  <joint
    name="DRV_RR_joint"
    type="continuous">
    <origin
      xyz="-0.021614 0.10378 0.015418"
      rpy="-1.5708 0 0" />
    <parent
      link="STR_RR_link" />
    <child
      link="DRV_RR_link" />
    <axis
      xyz="0 0 1" />
  </joint>
  <link
    name="RFB_link">
    <inertial>
      <origin
        xyz="-0.0263258310482531 0.00628258066571832 1.60029852358315E-05"
        rpy="0 0 0" />
      <mass
        value="0.0924731809037187" />
      <inertia
        ixx="0.000113483415744406"
        ixy="-4.18265340510287E-07"
        ixz="1.98435780729848E-09"
        iyy="0.000122753676437502"
        iyz="4.34830525832149E-09"
        izz="2.29318171883021E-05" />
    </inertial>
    <visual>
      <origin
        xyz="0 0 0"
        rpy="0 0 0" />
      <geometry>
        <mesh
          filename="package://ExoMy_Model_Full/meshes/RFB_link.STL" />
      </geometry>
      <material
        name="">
        <color
          rgba="0.298039215686275 0.298039215686275 0.298039215686275 1" />
      </material>
    </visual>
    <collision>
      <origin
        xyz="0 0 0"
        rpy="0 0 0" />
      <geometry>
        <mesh
          filename="package://ExoMy_Model_Full/meshes/RFB_link.STL" />
      </geometry>
    </collision>
  </link>
  <joint
    name="RFB_joint"
    type="revolute">
    <origin
      xyz="0.055 -0.062 0.017"
      rpy="1.5549 0 1.5708" />
    <parent
      link="base_link" />
    <child
      link="RFB_link" />
    <axis
      xyz="0 0 1" />
    <limit
      lower="0"
      upper="0"
      effort="0"
      velocity="0" />
  </joint>
  <link
    name="STR_RF_link">
    <inertial>
      <origin
        xyz="-0.0344555107840984 -0.0491790839210982 0.0802255353642999"
        rpy="0 0 0" />
      <mass
        value="0.0711731123513564" />
      <inertia
        ixx="3.36872678189227E-05"
        ixy="-4.74135711620255E-06"
        ixz="-8.08388204163537E-09"
        iyy="1.59192030092836E-05"
        iyz="-1.40514255182746E-07"
        izz="4.10633381534301E-05" />
    </inertial>
    <visual>
      <origin
        xyz="0 0 0"
        rpy="0 0 0" />
      <geometry>
        <mesh
          filename="package://ExoMy_Model_Full/meshes/STR_RF_link.STL" />
      </geometry>
      <material
        name="">
        <color
          rgba="0.698039215686274 0.698039215686274 0.698039215686274 1" />
      </material>
    </visual>
    <collision>
      <origin
        xyz="0 0 0"
        rpy="0 0 0" />
      <geometry>
        <mesh
          filename="package://ExoMy_Model_Full/meshes/STR_RF_link.STL" />
      </geometry>
    </collision>
  </link>
  <joint
    name="STR_RF_joint"
    type="revolute">
    <origin
      xyz="-0.019775 0 0"
      rpy="0 0 0" />
    <parent
      link="RFB_link" />
    <child
      link="STR_RF_link" />
    <axis
      xyz="0 0 1" />
    <limit
      lower="0"
      upper="0"
      effort="0"
      velocity="0" />
  </joint>
  <link
    name="DRV_RF_link">
    <inertial>
      <origin
        xyz="-0.016532818451544 -0.0728723179165183 0.0800000439280448"
        rpy="0 0 0" />
      <mass
        value="0.0569725827075563" />
      <inertia
        ixx="8.04986816304343E-05"
        ixy="6.30117671071577E-08"
        ixz="-1.21312260936329E-11"
        iyy="5.21106389985383E-05"
        iyz="1.4280803527455E-11"
        izz="5.23057476713964E-05" />
    </inertial>
    <visual>
      <origin
        xyz="0 0 0"
        rpy="0 0 0" />
      <geometry>
        <mesh
          filename="package://ExoMy_Model_Full/meshes/DRV_RF_link.STL" />
      </geometry>
      <material
        name="">
        <color
          rgba="0.968627450980392 0.87843137254902 0.6 1" />
      </material>
    </visual>
    <collision>
      <origin
        xyz="0 0 0"
        rpy="0 0 0" />
      <geometry>
        <mesh
          filename="package://ExoMy_Model_Full/meshes/DRV_RF_link.STL" />
      </geometry>
    </collision>
  </link>
  <joint
    name="DRV_RF_joint"
    type="continuous">
    <origin
      xyz="0.0043862 0 0"
      rpy="0 0 0" />
    <parent
      link="STR_RF_link" />
    <child
      link="DRV_RF_link" />
    <axis
      xyz="0 0 -1" />
  </joint>
  <link
    name="STR_RM_link">
    <inertial>
      <origin
        xyz="-0.0344570290035743 -0.0491787008492301 -0.0802254845265562"
        rpy="0 0 0" />
      <mass
        value="0.0711741620458433" />
      <inertia
        ixx="3.36879468050997E-05"
        ixy="-4.7385070237828E-06"
        ixz="8.97622796968714E-09"
        iyy="1.59152316780872E-05"
        iyz="1.40352149406493E-07"
        izz="4.10598352109841E-05" />
    </inertial>
    <visual>
      <origin
        xyz="0 0 0"
        rpy="0 0 0" />
      <geometry>
        <mesh
          filename="package://ExoMy_Model_Full/meshes/STR_RM_link.STL" />
      </geometry>
      <material
        name="">
        <color
          rgba="0.698039215686274 0.698039215686274 0.698039215686274 1" />
      </material>
    </visual>
    <collision>
      <origin
        xyz="0 0 0"
        rpy="0 0 0" />
      <geometry>
        <mesh
          filename="package://ExoMy_Model_Full/meshes/STR_RM_link.STL" />
      </geometry>
    </collision>
  </link>
  <joint
    name="STR_RM_joint"
    type="continuous">
    <origin
      xyz="-0.019775 0 0"
      rpy="0 0 0" />
    <parent
      link="RFB_link" />
    <child
      link="STR_RM_link" />
    <axis
      xyz="0 0 1" />
  </joint>
  <link
    name="DRV_RM_link">
    <inertial>
      <origin
        xyz="-0.0165328184402209 -0.0728723179165187 -0.0799999560369216"
        rpy="0 0 0" />
      <mass
        value="0.0569725827075566" />
      <inertia
        ixx="8.04986816304345E-05"
        ixy="6.30117671071895E-08"
        ixz="-1.21312260680937E-11"
        iyy="5.21106389985385E-05"
        iyz="1.42808035922001E-11"
        izz="5.23057476713965E-05" />
    </inertial>
    <visual>
      <origin
        xyz="0 0 0"
        rpy="0 0 0" />
      <geometry>
        <mesh
          filename="package://ExoMy_Model_Full/meshes/DRV_RM_link.STL" />
      </geometry>
      <material
        name="">
        <color
          rgba="0.968627450980392 0.87843137254902 0.6 1" />
      </material>
    </visual>
    <collision>
      <origin
        xyz="0 0 0"
        rpy="0 0 0" />
      <geometry>
        <mesh
          filename="package://ExoMy_Model_Full/meshes/DRV_RM_link.STL" />
      </geometry>
    </collision>
  </link>
  <joint
    name="DRV_RM_joint"
    type="continuous">
    <origin
      xyz="0.0043862 0 0"
      rpy="0 0 0" />
    <parent
      link="STR_RM_link" />
    <child
      link="DRV_RM_link" />
    <axis
      xyz="0 0 -1" />
  </joint>
  <link
    name="LFB_link">
    <inertial>
      <origin
        xyz="-0.026325831044373 0.00628258071143433 1.60029202154882E-05"
        rpy="0 0 0" />
      <mass
        value="0.0924731806442644" />
      <inertia
        ixx="0.000113483417193971"
        ixy="-4.18265325949264E-07"
        ixz="1.9843474849086E-09"
        iyy="0.000122753677991828"
        iyz="4.34816478644605E-09"
        izz="2.29318170765755E-05" />
    </inertial>
    <visual>
      <origin
        xyz="0 0 0"
        rpy="0 0 0" />
      <geometry>
        <mesh
          filename="package://ExoMy_Model_Full/meshes/LFB_link.STL" />
      </geometry>
      <material
        name="">
        <color
          rgba="0.298039215686275 0.298039215686275 0.298039215686275 1" />
      </material>
    </visual>
    <collision>
      <origin
        xyz="0 0 0"
        rpy="0 0 0" />
      <geometry>
        <mesh
          filename="package://ExoMy_Model_Full/meshes/LFB_link.STL" />
      </geometry>
    </collision>
  </link>
  <joint
    name="LFB_joint"
    type="continuous">
    <origin
      xyz="0.055 0.062 0.017"
      rpy="1.5708 0 -1.5708" />
    <parent
      link="base_link" />
    <child
      link="LFB_link" />
    <axis
      xyz="0 0 1" />
  </joint>
  <link
    name="STR_LF_link">
    <inertial>
      <origin
        xyz="-0.0344570291004626 -0.0491787009553567 -0.0802254862855219"
        rpy="0 0 0" />
      <mass
        value="0.0711741624806841" />
      <inertia
        ixx="3.3687947847999E-05"
        ixy="-4.73850731914466E-06"
        ixz="8.98028473566602E-09"
        iyy="1.59152321238694E-05"
        iyz="1.40355471129958E-07"
        izz="4.10598360484866E-05" />
    </inertial>
    <visual>
      <origin
        xyz="0 0 0"
        rpy="0 0 0" />
      <geometry>
        <mesh
          filename="package://ExoMy_Model_Full/meshes/STR_LF_link.STL" />
      </geometry>
      <material
        name="">
        <color
          rgba="0.698039215686274 0.698039215686274 0.698039215686274 1" />
      </material>
    </visual>
    <collision>
      <origin
        xyz="0 0 0"
        rpy="0 0 0" />
      <geometry>
        <mesh
          filename="package://ExoMy_Model_Full/meshes/STR_LF_link.STL" />
      </geometry>
    </collision>
  </link>
  <joint
    name="STR_LF_joint"
    type="continuous">
    <origin
      xyz="-0.019775 0 0"
      rpy="0 0 0" />
    <parent
      link="LFB_link" />
    <child
      link="STR_LF_link" />
    <axis
      xyz="0 0 1" />
  </joint>
  <link
    name="DRV_LF_link">
    <inertial>
      <origin
        xyz="-0.0165328184515428 -0.0728723179165186 -0.0799999560369219"
        rpy="0 0 0" />
      <mass
        value="0.0569725827075566" />
      <inertia
        ixx="8.04986816304343E-05"
        ixy="6.30117671071824E-08"
        ixz="-1.21312268806798E-11"
        iyy="5.21106389985386E-05"
        iyz="1.42808035659953E-11"
        izz="5.23057476713962E-05" />
    </inertial>
    <visual>
      <origin
        xyz="0 0 0"
        rpy="0 0 0" />
      <geometry>
        <mesh
          filename="package://ExoMy_Model_Full/meshes/DRV_LF_link.STL" />
      </geometry>
      <material
        name="">
        <color
          rgba="0.968627450980392 0.87843137254902 0.6 1" />
      </material>
    </visual>
    <collision>
      <origin
        xyz="0 0 0"
        rpy="0 0 0" />
      <geometry>
        <mesh
          filename="package://ExoMy_Model_Full/meshes/DRV_LF_link.STL" />
      </geometry>
    </collision>
  </link>
  <joint
    name="DRV_LF_joint"
    type="continuous">
    <origin
      xyz="0.0043862 0 0"
      rpy="0 0 0" />
    <parent
      link="STR_LF_link" />
    <child
      link="DRV_LF_link" />
    <axis
      xyz="0 0 1" />
  </joint>
  <link
    name="STR_LM_link">
    <inertial>
      <origin
        xyz="-0.0344555119320244 -0.0491790863888992 0.0802255333119942"
        rpy="0 0 0" />
      <mass
        value="0.0711731050167323" />
      <inertia
        ixx="3.3687265159018E-05"
        ixy="-4.74135535852495E-06"
        ixz="-8.07921081337301E-09"
        iyy="1.59192004795905E-05"
        iyz="-1.40511475060456E-07"
        izz="4.10633342810777E-05" />
    </inertial>
    <visual>
      <origin
        xyz="0 0 0"
        rpy="0 0 0" />
      <geometry>
        <mesh
          filename="package://ExoMy_Model_Full/meshes/STR_LM_link.STL" />
      </geometry>
      <material
        name="">
        <color
          rgba="0.698039215686274 0.698039215686274 0.698039215686274 1" />
      </material>
    </visual>
    <collision>
      <origin
        xyz="0 0 0"
        rpy="0 0 0" />
      <geometry>
        <mesh
          filename="package://ExoMy_Model_Full/meshes/STR_LM_link.STL" />
      </geometry>
    </collision>
  </link>
  <joint
    name="STR_LM_joint"
    type="continuous">
    <origin
      xyz="-0.019775 0 0"
      rpy="0 0 0" />
    <parent
      link="LFB_link" />
    <child
      link="STR_LM_link" />
    <axis
      xyz="0 0 1" />
  </joint>
  <link
    name="DRV_LM_link">
    <inertial>
      <origin
        xyz="-0.016532818462866 -0.0728723179165183 0.0800000439280445"
        rpy="0 0 0" />
      <mass
        value="0.0569725827075566" />
      <inertia
        ixx="8.04986816304344E-05"
        ixy="6.30117671071744E-08"
        ixz="-1.21312268738888E-11"
        iyy="5.21106389985386E-05"
        iyz="1.42808035451304E-11"
        izz="5.23057476713963E-05" />
    </inertial>
    <visual>
      <origin
        xyz="0 0 0"
        rpy="0 0 0" />
      <geometry>
        <mesh
          filename="package://ExoMy_Model_Full/meshes/DRV_LM_link.STL" />
      </geometry>
      <material
        name="">
        <color
          rgba="0.968627450980392 0.87843137254902 0.6 1" />
      </material>
    </visual>
    <collision>
      <origin
        xyz="0 0 0"
        rpy="0 0 0" />
      <geometry>
        <mesh
          filename="package://ExoMy_Model_Full/meshes/DRV_LM_link.STL" />
      </geometry>
    </collision>
  </link>
  <joint
    name="DRV_LM_joint"
    type="continuous">
    <origin
      xyz="0.0043862 0 0"
      rpy="0 0 0" />
    <parent
      link="STR_LM_link" />
    <child
      link="DRV_LM_link" />
    <axis
      xyz="0 0 1" />
  </joint>
  <link
    name="head_link">
    <inertial>
      <origin
        xyz="4.05099172861749E-05 0.0118850586865648 0.0302442059611974"
        rpy="0 0 0" />
      <mass
        value="0.078891512690109" />
      <inertia
        ixx="6.70251107353368E-05"
        ixy="2.39510957059722E-09"
        ixz="-1.02874991606387E-08"
        iyy="0.000206696832834381"
        iyz="-5.15030227255928E-07"
        izz="0.000246607733219875" />
    </inertial>
    <visual>
      <origin
        xyz="0 0 0"
        rpy="0 0 0" />
      <geometry>
        <mesh
          filename="package://ExoMy_Model_Full/meshes/head_link.STL" />
      </geometry>
      <material
        name="">
        <color
          rgba="0.968627450980392 0.87843137254902 0.6 1" />
      </material>
    </visual>
    <collision>
      <origin
        xyz="0 0 0"
        rpy="0 0 0" />
      <geometry>
        <mesh
          filename="package://ExoMy_Model_Full/meshes/head_link.STL" />
      </geometry>
    </collision>
  </link>
  <joint
    name="head_joint"
    type="fixed">
    <origin
      xyz="0.027 0 0.26928"
      rpy="1.5708 0 1.5708" />
    <parent
      link="base_link" />
    <child
      link="head_link" />
    <axis
      xyz="0 0 0" />
  </joint>
  <link
    name="eyewhite_link">
    <inertial>
      <origin
        xyz="0.0519999879024582 -3.12462373083244E-05 0.000860409568077425"
        rpy="0 0 0" />
      <mass
        value="0.00447909534854348" />
      <inertia
        ixx="4.71996017145732E-07"
        ixy="3.02527120036996E-13"
        ixz="-2.59196121266908E-14"
        iyy="4.71644858227356E-07"
        iyz="1.94300295539225E-11"
        izz="9.38560485421757E-07" />
    </inertial>
    <visual>
      <origin
        xyz="0 0 0"
        rpy="0 0 0" />
      <geometry>
        <mesh
          filename="package://ExoMy_Model_Full/meshes/eyewhite_link.STL" />
      </geometry>
      <material
        name="">
        <color
          rgba="1 1 1 1" />
      </material>
    </visual>
    <collision>
      <origin
        xyz="0 0 0"
        rpy="0 0 0" />
      <geometry>
        <mesh
          filename="package://ExoMy_Model_Full/meshes/eyewhite_link.STL" />
      </geometry>
    </collision>
  </link>
  <joint
    name="eyewhite_joint"
    type="fixed">
    <origin
      xyz="-0.052 0.024 0.04"
      rpy="0 0 0" />
    <parent
      link="head_link" />
    <child
      link="eyewhite_link" />
    <axis
      xyz="0 0 0" />
  </joint>
  <link
    name="pupils_link">
    <inertial>
      <origin
        xyz="-0.0519174840998746 0.00748285919842917 0.000632252497896557"
        rpy="0 0 0" />
      <mass
        value="0.00180370592614686" />
      <inertia
        ixx="5.78044279193744E-08"
        ixy="-3.10353112484797E-10"
        ixz="2.38207763822241E-10"
        iyy="5.4642923289686E-08"
        iyz="2.44973736424874E-09"
        izz="1.06940274596115E-07" />
    </inertial>
    <visual>
      <origin
        xyz="0 0 0"
        rpy="0 0 0" />
      <geometry>
        <mesh
          filename="package://ExoMy_Model_Full/meshes/pupils_link.STL" />
      </geometry>
      <material
        name="">
        <color
          rgba="0.101960784313725 0.101960784313725 0.101960784313725 1" />
      </material>
    </visual>
    <collision>
      <origin
        xyz="0 0 0"
        rpy="0 0 0" />
      <geometry>
        <mesh
          filename="package://ExoMy_Model_Full/meshes/pupils_link.STL" />
      </geometry>
    </collision>
  </link>
  <joint
    name="pupils_joint"
    type="fixed">
    <origin
      xyz="0.10461 -0.0044591 0.002"
      rpy="0 0 0.13494" />
    <parent
      link="eyewhite_link" />
    <child
      link="pupils_link" />
    <axis
      xyz="0 0 0" />
  </joint>
  <link
    name="cam_link">
    <inertial>
      <origin
        xyz="-0.00249086473821686 0.000136649009533494 0.000569820673845034"
        rpy="0 0 0" />
      <mass
        value="0.00115745344893818" />
      <inertia
        ixx="3.97290092554314E-08"
        ixy="1.65336506578874E-13"
        ixz="-3.60412180475581E-11"
        iyy="2.88827920072803E-08"
        iyz="-2.52492241388416E-13"
        izz="6.76913771029684E-08" />
    </inertial>
    <visual>
      <origin
        xyz="0 0 0"
        rpy="0 0 0" />
      <geometry>
        <mesh
          filename="package://ExoMy_Model_Full/meshes/cam_link.STL" />
      </geometry>
      <material
        name="">
        <color
          rgba="0.792156862745098 0.819607843137255 0.933333333333333 1" />
      </material>
    </visual>
    <collision>
      <origin
        xyz="0 0 0"
        rpy="0 0 0" />
      <geometry>
        <mesh
          filename="package://ExoMy_Model_Full/meshes/cam_link.STL" />
      </geometry>
    </collision>
  </link>
  <joint
    name="cam_joint"
    type="fixed">
    <origin
      xyz="9.4215E-05 0.0031547 0.036"
      rpy="0 0 1.5708" />
    <parent
      link="head_link" />
    <child
      link="cam_link" />
    <axis
      xyz="0 0 0" />
  </joint>
  <link
    name="hat_link">
    <inertial>
      <origin
        xyz="3.1955815901622E-08 0.0294025205083059 0.0152014899719377"
        rpy="0 0 0" />
      <mass
        value="0.0446228233973554" />
      <inertia
        ixx="4.85170602784381E-05"
        ixy="-7.36561851651266E-11"
        ixz="-4.45696698654547E-11"
        iyy="0.000137144944737089"
        iyz="-1.51319761954045E-05"
        izz="0.000157930625148711" />
    </inertial>
    <visual>
      <origin
        xyz="0 0 0"
        rpy="0 0 0" />
      <geometry>
        <mesh
          filename="package://ExoMy_Model_Full/meshes/hat_link.STL" />
      </geometry>
      <material
        name="">
        <color
          rgba="0.698039215686274 0.698039215686274 0.698039215686274 1" />
      </material>
    </visual>
    <collision>
      <origin
        xyz="0 0 0"
        rpy="0 0 0" />
      <geometry>
        <mesh
          filename="package://ExoMy_Model_Full/meshes/hat_link.STL" />
      </geometry>
    </collision>
  </link>
  <joint
    name="hat_joint"
    type="fixed">
    <origin
      xyz="0 0 0"
      rpy="0 0 0" />
    <parent
      link="head_link" />
    <child
      link="hat_link" />
    <axis
      xyz="0 0 0" />
  </joint>
  <link
    name="bling_link">
    <inertial>
      <origin
        xyz="0 0 0"
        rpy="0 0 0" />
      <mass
        value="0" />
      <inertia
        ixx="0"
        ixy="0"
        ixz="0"
        iyy="0"
        iyz="0"
        izz="0" />
    </inertial>
    <visual>
      <origin
        xyz="0 0 0"
        rpy="0 0 0" />
      <geometry>
        <mesh
          filename="package://ExoMy_Model_Full/meshes/bling_link.STL" />
      </geometry>
      <material
        name="">
        <color
          rgba="1 1 1 1" />
      </material>
    </visual>
    <collision>
      <origin
        xyz="0 0 0"
        rpy="0 0 0" />
      <geometry>
        <mesh
          filename="package://ExoMy_Model_Full/meshes/bling_link.STL" />
      </geometry>
    </collision>
  </link>
  <joint
    name="bling_joint"
    type="fixed">
    <origin
      xyz="0.08 0.0225 0"
      rpy="1.5708 0 1.5708" />
    <parent
      link="base_link" />
    <child
      link="bling_link" />
    <axis
      xyz="0 0 0" />
  </joint>
</robot>